ERROR 2016-02-22 19:26:36 c:\python27\lib\site-packages\django\core\handlers\base.py base 212 Internal Server Error: / status_code:500
Traceback (most recent call last):
  File "C:\Python27\lib\site-packages\django\core\handlers\base.py", line 133, in get_response
    raise ValueError("The view %s.%s didn't return an HttpResponse object." % (callback.__module__, view_name))
ValueError: The view zyf_cms.views.login didn't return an HttpResponse object.
WARNING 2016-02-22 19:26:41 c:\python27\lib\site-packages\django\core\handlers\base.py base 146 Not Found: /favicon.ico status_code:404
ERROR 2016-02-22 19:26:57 c:\python27\lib\site-packages\django\core\handlers\base.py base 212 Internal Server Error: /admin/cookbook_list status_code:500
Traceback (most recent call last):
  File "C:\Python27\lib\site-packages\django\core\handlers\base.py", line 92, in get_response
    response = middleware_method(request)
  File "C:\Python27\lib\site-packages\django\middleware\common.py", line 70, in process_request
    urlresolvers.is_valid_path("%s/" % request.path_info, urlconf)):
  File "C:\Python27\lib\site-packages\django\core\urlresolvers.py", line 551, in is_valid_path
    resolve(path, urlconf)
  File "C:\Python27\lib\site-packages\django\core\urlresolvers.py", line 440, in resolve
    return get_resolver(urlconf).resolve(path)
  File "C:\Python27\lib\site-packages\django\core\urlresolvers.py", line 321, in resolve
    sub_match = pattern.resolve(new_path)
  File "C:\Python27\lib\site-packages\django\core\urlresolvers.py", line 321, in resolve
    sub_match = pattern.resolve(new_path)
  File "C:\Python27\lib\site-packages\django\core\urlresolvers.py", line 223, in resolve
    return ResolverMatch(self.callback, args, kwargs, self.name)
  File "C:\Python27\lib\site-packages\django\core\urlresolvers.py", line 230, in callback
    self._callback = get_callable(self._callback_str)
  File "C:\Python27\lib\site-packages\django\utils\functional.py", line 29, in wrapper
    result = func(*args)
  File "C:\Python27\lib\site-packages\django\core\urlresolvers.py", line 97, in get_callable
    mod = import_module(mod_name)
  File "C:\Python27\lib\site-packages\django\utils\importlib.py", line 35, in import_module
    __import__(name)
  File "D:/ProjData/Pycharm/zyf_cms\admin\views.py", line 11, in <module>
    from admin.actions import AdminManager
  File "D:/ProjData/Pycharm/zyf_cms\admin\actions.py", line 4, in <module>
    from wx_oos.models import Cookbook, FoodType
ImportError: No module named wx_oos.models
WARNING 2016-02-22 19:28:09 c:\python27\lib\site-packages\django\core\handlers\base.py base 146 Not Found: /favicon.ico status_code:404
ERROR 2016-02-22 20:07:45 c:\python27\lib\site-packages\django\core\handlers\base.py base 212 Internal Server Error: / status_code:500
Traceback (most recent call last):
  File "C:\Python27\lib\site-packages\django\core\handlers\base.py", line 133, in get_response
    raise ValueError("The view %s.%s didn't return an HttpResponse object." % (callback.__module__, view_name))
ValueError: The view zyf_cms.views.login didn't return an HttpResponse object.
WARNING 2016-02-22 20:07:49 c:\python27\lib\site-packages\django\core\handlers\base.py base 146 Not Found: /favicon.ico status_code:404
ERROR 2016-02-22 20:08:09 c:\python27\lib\site-packages\django\core\handlers\base.py base 212 Internal Server Error: /logout/ status_code:500
Traceback (most recent call last):
  File "C:\Python27\lib\site-packages\django\core\handlers\base.py", line 115, in get_response
    response = callback(request, *callback_args, **callback_kwargs)
  File "C:\Python27\lib\site-packages\django\views\decorators\csrf.py", line 77, in wrapped_view
    return view_func(*args, **kwargs)
  File "C:/Users/Selwyn/Desktop/zyf_cms\zyf_cms\views.py", line 20, in logout
    request.session.flush()
  File "C:\Python27\lib\site-packages\django\contrib\sessions\backends\base.py", line 264, in flush
    self.create()
  File "C:\Python27\lib\site-packages\django\contrib\sessions\backends\db.py", line 30, in create
    self._session_key = self._get_new_session_key()
  File "C:\Python27\lib\site-packages\django\contrib\sessions\backends\base.py", line 142, in _get_new_session_key
    if not self.exists(session_key):
  File "C:\Python27\lib\site-packages\django\contrib\sessions\backends\db.py", line 26, in exists
    return Session.objects.filter(session_key=session_key).exists()
  File "C:\Python27\lib\site-packages\django\db\models\query.py", line 596, in exists
    return self.query.has_results(using=self.db)
  File "C:\Python27\lib\site-packages\django\db\models\sql\query.py", line 442, in has_results
    return bool(compiler.execute_sql(SINGLE))
  File "C:\Python27\lib\site-packages\django\db\models\sql\compiler.py", line 839, in execute_sql
    cursor = self.connection.cursor()
  File "C:\Python27\lib\site-packages\django\db\backends\__init__.py", line 324, in cursor
    cursor = self.make_debug_cursor(self._cursor())
  File "C:\Python27\lib\site-packages\django\db\backends\mysql\base.py", line 405, in _cursor
    self.connection = Database.connect(**kwargs)
  File "C:\Python27\lib\site-packages\MySQLdb\__init__.py", line 81, in Connect
    return Connection(*args, **kwargs)
  File "C:\Python27\lib\site-packages\MySQLdb\connections.py", line 187, in __init__
    super(Connection, self).__init__(*args, **kwargs2)
OperationalError: (1049, "Unknown database 'zyf_cms'")
